Workbook
Name \a: #REF!
Name \p: #REF!
Name \S: #REF!
Name _____xlnm._FilterDatabase: #N/A
Name _____xlnm.Database: #N/A
Name _____xlnm.Print_Area: #N/A
Name _____xlnm.Print_Titles: #N/A
Name ____xlnm._FilterDatabase: #N/A
Name ____xlnm.Database: #N/A
Name ____xlnm.Print_Area: #N/A
Name ____xlnm.Print_Titles: #N/A
Name ___EMS753: #REF!
Name ___xlnm._FilterDatabase: #N/A
Name ___xlnm.Database: #N/A
Name ___xlnm.Print_Area: #N/A
Name ___xlnm.Print_Titles: #N/A
Name __EMS753: #REF!
Name __P5: #N/A
Name __S10: #N/A
Name __xlnm._FilterDatabase: #N/A
Name __xlnm.Database: #N/A
Name __xlnm.Print_Area: #N/A
Name __xlnm.Print_Titles: #N/A
Name _1_: #REF!
Name _1_0Datab: [2]BOM!#REF!
Name _10083241: "table5"
Name _175_0INVENT: [3]Consolidated!#REF!
Name _178_0STAFFS___OT: [3]Consolidated!#REF!
Name _181INVENT: [3]Consolidated!#REF!
Name _184STAFFS___OT: [3]Consolidated!#REF!
Name _2C: #REF!
Name _2Datab: [2]BOM!#REF!
Name _3_0Datab: [2]BOM!#REF!
Name _3_0INVENT: [3]Consolidated!#REF!
Name _4_0STAFFS___OT: [3]Consolidated!#REF!
Name _5INVENT: [3]Consolidated!#REF!
Name _6Datab: [2]BOM!#REF!
Name _6STAFFS___OT: [3]Consolidated!#REF!
Name _A: #REF!
Name _a1: {"'1-TheatreBkgs'!$A$1:$L$102"}
Name _a1254: #REF!
Name _a2: {"'1-TheatreBkgs'!$A$1:$L$102"}
Name _A3: #N/A
Name _a4: {"'1-TheatreBkgs'!$A$1:$L$102"}
Name _ab1: [4]!_ab1
Name _ab2: [4]!_ab2
Name _ab3: [4]!_ab3
Name _aki1: #N/A
Name _AND1: #N/A
Name _AND2: #N/A
Name _AND3: #N/A
Name _b: #REF!
Name _bom7023: #REF!
Name _BUS1: #REF!
Name _BUS10: #REF!
Name _BUS11: #REF!
Name _BUS12: #REF!
Name _BUS13: #REF!
Name _BUS14: #REF!
Name _BUS15: #REF!

Sheet Weekly Capacity (PE)
F1: 46020 | G1: =F1+7 -> 46027 | H1: =G1+7 -> 46034 | I1: =H1+7 -> 46041 | J1: =I1+7 -> 46048 | K1: =J1+7 -> 46055 | L1: =K1+7 -> 46062 | M1: =L1+7 -> 46069 | N1: =M1+7 -> 46076 | ... R1: =Q1+7 -> 46104 | T1: =R1+7 -> 46111 | U1: =T1+7 -> 46118 | V1: =U1+7 -> 46125 | W1: =V1+7 -> 46132 | X1: =W1+7 -> 46139 | Y1: =X1+7 -> 46146 | Z1: =Y1+7 -> 46153 | AA1: =Z1+7 -> 46160 | AB1: =AA1+7 -> 46167 | ... AF1: =AE1+7 -> 46195 | AH1: =AF1+7 -> 46202 | AI1: =AH1+7 -> 46209 | AJ1: =AI1+7 -> 46216 | AK1: =AJ1+7 -> 46223 | AL1: =AK1+7 -> 46230 | AM1: =AL1+7 -> 46237 | AN1: =AM1+7 -> 46244 | AO1: =AN1+7 -> 46251 | AP1: =AO1+7 -> 46258 | ... AT1: =AS1+7 -> 46286 | AV1: =AT1+7 -> 46293 | AW1: =AV1+7 -> 46300 | AX1: =AW1+7 -> 46307 | AY1: =AX1+7 -> 46314 | AZ1: =AY1+7 -> 46321 | BA1: =AZ1+7 -> 46328 | BB1: =BA1+7 -> 46335 | BC1: =BB1+7 -> 46342 | BD1: =BC1+7 -> 46349 | ... BH1: =BG1+7 -> 46377
F2: WQ326 | G2: Target 300K | S2: 190K | T2: WQ426 | AG2: 300K | AH2: WQ127 | AU2: 330K | AV2: WQ227 | BI2: 430K
F3: WW01 | G3: WW02 | H3: WW03 | I3: WW04 | J3: WW05 | K3: WW06 | L3: WW07 | M3: WW08 | N3: WW09 | O3: WW10 | P3: WW11 | Q3: WW12 | R3: WW13 | S3: Q326 | T3: WW01 | U3: WW02 | V3: WW03 | W3: WW04 | X3: WW05 | Y3: WW06 | Z3: WW07 | AA3: WW08 | AB3: WW09 | AC3: WW10 | AD3: WW11 | AE3: WW12 | AF3: WW13 | AG3: Q426 | AH3: WW01 | AI3: WW02 | AJ3: WW03 | AK3: WW04 | AL3: WW05 | AM3: WW06 | AN3: WW07 | AO3: WW08 | AP3: WW09 | AQ3: WW10 | AR3: WW11 | AS3: WW12 | AT3: WW13 | AU3: Q127 | AV3: WW01 | AW3: WW02 | AX3: WW03 | AY3: WW04 | AZ3: WW05 | BA3: WW06 | BB3: WW07 | BC3: WW08 | BD3: WW09 | BE3: WW10 | BF3: WW11 | BG3: WW12 | BH3: WW13 | BI3: Q227 | BJ3: Q327 | BK3: Q427 | BL3: Q128 | BM3: Q228
D4: Working days | F4: =$S$4/13 -> 6.4615385 | G4: =F4 -> 6.4615385 | H4: =G4 -> 6.4615385 | I4: =H4 -> 6.4615385 | J4: =I4 -> 6.4615385 | K4: =J4 -> 6.4615385 | L4: =K4 -> 6.4615385 | M4: =L4 -> 6.4615385 | N4: =M4 -> 6.4615385 | ... R4: =Q4 -> 6.4615385 | S4: 84 | T4: =$S$4/13 -> 6.4615385 | U4: =T4 -> 6.4615385 | V4: =U4 -> 6.4615385 | W4: =V4 -> 6.4615385 | X4: =W4 -> 6.4615385 | Y4: =X4 -> 6.4615385 | Z4: =Y4 -> 6.4615385 | AA4: =Z4 -> 6.4615385 | AB4: =AA4 -> 6.4615385 | ... AF4: =AE4 -> 6.4615385 | AG4: 84 | AH4: =$S$4/13 -> 6.4615385 | AI4: =AH4 -> 6.4615385 | AJ4: =AI4 -> 6.4615385 | AK4: =AJ4 -> 6.4615385 | AL4: =AK4 -> 6.4615385 | AM4: =AL4 -> 6.4615385 | AN4: =AM4 -> 6.4615385 | AO4: =AN4 -> 6.4615385 | AP4: =AO4 -> 6.4615385 | ... AT4: =AS4 -> 6.4615385 | AU4: 84 | AV4: =$S$4/13 -> 6.4615385 | AW4: =AV4 -> 6.4615385 | AX4: =AW4 -> 6.4615385 | AY4: =AX4 -> 6.4615385 | AZ4: =AY4 -> 6.4615385 | BA4: =AZ4 -> 6.4615385 | BB4: =BA4 -> 6.4615385 | BC4: =BB4 -> 6.4615385 | BD4: =BC4 -> 6.4615385 | ... BH4: =BG4 -> 6.4615385 | BI4: 84 | BJ4: 84 | BK4: 84 | BL4: 84 | BM4: 84
D5: Working Hrs | F5: 21 | G5: =F5 -> 21 | H5: =G5 -> 21 | I5: =H5 -> 21 | J5: =I5 -> 21 | K5: =J5 -> 21 | L5: =K5 -> 21 | M5: =L5 -> 21 | N5: =M5 -> 21 | ... R5: =Q5 -> 21 | S5: 21 | T5: 21 | U5: =T5 -> 21 | V5: =U5 -> 21 | W5: =V5 -> 21 | X5: =W5 -> 21 | Y5: =X5 -> 21 | Z5: =Y5 -> 21 | AA5: =Z5 -> 21 | AB5: =AA5 -> 21 | ... AF5: =AE5 -> 21 | AG5: 21 | AH5: 21 | AI5: =AH5 -> 21 | AJ5: =AI5 -> 21 | AK5: =AJ5 -> 21 | AL5: =AK5 -> 21 | AM5: =AL5 -> 21 | AN5: =AM5 -> 21 | AO5: =AN5 -> 21 | AP5: =AO5 -> 21 | ... AT5: =AS5 -> 21 | AU5: 21 | AV5: 21 | AW5: =AV5 -> 21 | AX5: =AW5 -> 21 | AY5: =AX5 -> 21 | AZ5: =AY5 -> 21 | BA5: =AZ5 -> 21 | BB5: =BA5 -> 21 | BC5: =BB5 -> 21 | BD5: =BC5 -> 21 | ... BH5: =BG5 -> 21 | BI5: 21 | BJ5: 21 | BK5: 21 | BL5: 21 | BM5: 21
D7: Working days | F7: 6 | G7: 6 | H7: 6 | I7: 6 | J7: 6 | K7: 6 | L7: 6 | M7: 6 | N7: 6 | O7: 6 | P7: 6 | Q7: 6 | R7: 6 | S7: 78 | T7: 6 | U7: 6 | V7: 6 | W7: 6 | X7: 6 | Y7: 6 | Z7: 6 | AA7: 6 | AB7: 6 | AC7: 6 | AD7: 6 | AE7: 6 | AF7: 6 | AG7: 78 | AH7: 6 | AI7: 6 | AJ7: 6 | AK7: 6 | AL7: 6 | AM7: 6 | AN7: 6 | AO7: 6 | AP7: 6 | AQ7: 6 | AR7: 6 | AS7: 6 | AT7: 6 | AU7: 78 | AV7: 6 | AW7: 6 | AX7: 6 | AY7: 6 | AZ7: 6 | BA7: 6 | BB7: 6 | BC7: 6 | BD7: 6 | BE7: 6 | BF7: 6 | BG7: 6 | BH7: 6 | BI7: 78 | BJ7: 78 | BK7: 78 | BL7: 78 | BM7: 78
D8: Working Hrs | F8: 21 | G8: 21 | H8: 21 | I8: 21 | J8: 21 | K8: 21 | L8: 21 | M8: 21 | N8: 21 | O8: 21 | P8: 21 | Q8: 21 | R8: 21 | S8: 21 | T8: 21 | U8: 21 | V8: 21 | W8: 21 | X8: 21 | Y8: 21 | Z8: 21 | AA8: 21 | AB8: 21 | AC8: 21 | AD8: 21 | AE8: 21 | AF8: 21 | AG8: 21 | AH8: 21 | AI8: 21 | AJ8: 21 | AK8: 21 | AL8: 21 | AM8: 21 | AN8: 21 | AO8: 21 | AP8: 21 | AQ8: 21 | AR8: 21 | AS8: 21 | AT8: 21 | AU8: 21 | AV8: 21 | AW8: 21 | AX8: 21 | AY8: 21 | AZ8: 21 | BA8: 21 | BB8: 21 | BC8: 21 | BD8: 21 | BE8: 21 | BF8: 21 | BG8: 21 | BH8: 21 | BI8: 21 | BJ8: 21 | BK8: 21 | BL8: 21 | BM8: 21
D9: Demand S&OP
D10: Total build plan | F10: =$S10*F$4/SUM($F$4:$R$4) -> 37279.511 | G10: =$S10*G$4/SUM($F$4:$R$4) -> 37279.511 | H10: =$S10*H$4/SUM($F$4:$R$4) -> 37279.511 | I10: =$S10*I$4/SUM($F$4:$R$4) -> 37279.511 | J10: =$S10*J$4/SUM($F$4:$R$4) -> 37279.511 | K10: =$S10*K$4/SUM($F$4:$R$4) -> 37279.511 | L10: =$S10*L$4/SUM($F$4:$R$4) -> 37279.511 | M10: =$S10*M$4/SUM($F$4:$R$4) -> 37279.511 | ... R10: =$S10*R$4/SUM($F$4:$R$4) -> 37279.511 | S10: =SUM(S11:S15,S20:S21) -> 484633.65 | T10: =$AG10*T$4/SUM($T$4:$AF$4) -> 55380.14 | U10: =$AG10*U$4/SUM($T$4:$AF$4) -> 55380.14 | V10: =$AG10*V$4/SUM($T$4:$AF$4) -> 55380.14 | W10: =$AG10*W$4/SUM($T$4:$AF$4) -> 55380.14 | X10: =$AG10*X$4/SUM($T$4:$AF$4) -> 55380.14 | Y10: =$AG10*Y$4/SUM($T$4:$AF$4) -> 55380.14 | Z10: =$AG10*Z$4/SUM($T$4:$AF$4) -> 55380.14 | AA10: =$AG10*AA$4/SUM($T$4:$AF$4) -> 55380.14 | ... AF10: =$AG10*AF$4/SUM($T$4:$AF$4) -> 55380.14 | AG10: =SUM(AG11:AG15,AG20:AG21) -> 719941.82 | AH10: =$AG10*AH$4/SUM($T$4:$AF$4) -> 55380.14 | AI10: =$AG10*AI$4/SUM($T$4:$AF$4) -> 55380.14 | AJ10: =$AG10*AJ$4/SUM($T$4:$AF$4) -> 55380.14 | AK10: =$AG10*AK$4/SUM($T$4:$AF$4) -> 55380.14 | AL10: =$AG10*AL$4/SUM($T$4:$AF$4) -> 55380.14 | AM10: =$AG10*AM$4/SUM($T$4:$AF$4) -> 55380.14 | AN10: =$AG10*AN$4/SUM($T$4:$AF$4) -> 55380.14 | AO10: =$AG10*AO$4/SUM($T$4:$AF$4) -> 55380.14 | ... AT10: =$AG10*AT$4/SUM($T$4:$AF$4) -> 55380.14 | AU10: =SUM(AU11:AU15,AU20:AU21) -> 1718829.9 | AV10: =$AG10*AV$4/SUM($T$4:$AF$4) -> 55380.14 | AW10: =$AG10*AW$4/SUM($T$4:$AF$4) -> 55380.14 | AX10: =$AG10*AX$4/SUM($T$4:$AF$4) -> 55380.14 | AY10: =$AG10*AY$4/SUM($T$4:$AF$4) -> 55380.14 | AZ10: =$AG10*AZ$4/SUM($T$4:$AF$4) -> 55380.14 | BA10: =$AG10*BA$4/SUM($T$4:$AF$4) -> 55380.14 | BB10: =$AG10*BB$4/SUM($T$4:$AF$4) -> 55380.14 | BC10: =$AG10*BC$4/SUM($T$4:$AF$4) -> 55380.14 | ... BH10: =$AG10*BH$4/SUM($T$4:$AF$4) -> 55380.14 | BI10: =SUM(BI11:BI15,BI20:BI21) -> 1169535.9 | BJ10: =SUM(BJ11:BJ15,BJ20:BJ21) -> 1300568 | BK10: =SUM(BK11:BK15,BK20:BK21) -> 1297632.1 | BL10: =SUM(BL11:BL15,BL20:BL21) -> 1320538.8 | BM10: =SUM(BM11:BM15,BM20:BM21) -> 1434725.5
D11: Hoplite (FBG) 980 | F11: =$S11*F$4/SUM($F$4:$R$4) -> 13343.22 | G11: =$S11*G$4/SUM($F$4:$R$4) -> 13343.22 | H11: =$S11*H$4/SUM($F$4:$R$4) -> 13343.22 | I11: =$S11*I$4/SUM($F$4:$R$4) -> 13343.22 | J11: =$S11*J$4/SUM($F$4:$R$4) -> 13343.22 | K11: =$S11*K$4/SUM($F$4:$R$4) -> 13343.22 | L11: =$S11*L$4/SUM($F$4:$R$4) -> 13343.22 | M11: =$S11*M$4/SUM($F$4:$R$4) -> 13343.22 | ... R11: =$S11*R$4/SUM($F$4:$R$4) -> 13343.22 | S11: ='[64]Main Demand SOP'!I41 -> 173461.86 | T11: =$AG11*T$4/SUM($T$4:$AF$4) -> 21744.171 | U11: =$AG11*U$4/SUM($T$4:$AF$4) -> 21744.171 | V11: =$AG11*V$4/SUM($T$4:$AF$4) -> 21744.171 | W11: =$AG11*W$4/SUM($T$4:$AF$4) -> 21744.171 | X11: =$AG11*X$4/SUM($T$4:$AF$4) -> 21744.171 | Y11: =$AG11*Y$4/SUM($T$4:$AF$4) -> 21744.171 | Z11: =$AG11*Z$4/SUM($T$4:$AF$4) -> 21744.171 | AA11: =$AG11*AA$4/SUM($T$4:$AF$4) -> 21744.171 | ... AF11: =$AG11*AF$4/SUM($T$4:$AF$4) -> 21744.171 | AG11: ='[64]Main Demand SOP'!J41 -> 282674.23 | AH11: =$AU11*AH$4/SUM($AH$4:$AT$4) -> 53482.395 | AI11: =$AU11*AI$4/SUM($AH$4:$AT$4) -> 53482.395 | AJ11: =$AU11*AJ$4/SUM($AH$4:$AT$4) -> 53482.395 | AK11: =$AU11*AK$4/SUM($AH$4:$AT$4) -> 53482.395 | AL11: =$AU11*AL$4/SUM($AH$4:$AT$4) -> 53482.395 | AM11: =$AU11*AM$4/SUM($AH$4:$AT$4) -> 53482.395 | AN11: =$AU11*AN$4/SUM($AH$4:$AT$4) -> 53482.395 | AO11: =$AU11*AO$4/SUM($AH$4:$AT$4) -> 53482.395 | ... AT11: =$AU11*AT$4/SUM($AH$4:$AT$4) -> 53482.395 | AU11: ='[64]Main Demand SOP'!K41 -> 695271.13 | AV11: =$BL11*AV$4/SUM($AH$4:$AT$4) -> 34887.946 | AW11: =$BL11*AW$4/SUM($AH$4:$AT$4) -> 34887.946 | AX11: =$BL11*AX$4/SUM($AH$4:$AT$4) -> 34887.946 | AY11: =$BL11*AY$4/SUM($AH$4:$AT$4) -> 34887.946 | AZ11: =$BL11*AZ$4/SUM($AH$4:$AT$4) -> 34887.946 | BA11: =$BL11*BA$4/SUM($AH$4:$AT$4) -> 34887.946 | BB11: =$BL11*BB$4/SUM($AH$4:$AT$4) -> 34887.946 | BC11: =$BL11*BC$4/SUM($AH$4:$AT$4) -> 34887.946 | ... BH11: =$BL11*BH$4/SUM($AH$4:$AT$4) -> 34887.946 | BI11: ='[64]Main Demand SOP'!L41 -> 383527.84 | BJ11: ='[64]Main Demand SOP'!M41 -> 462516.49 | BK11: ='[64]Main Demand SOP'!N41 -> 460021.65 | BL11: ='[64]Main Demand SOP'!O41 -> 453543.3 | BM11: ='[64]Main Demand SOP'!P41 -> 452400 | BN11: =S11/$S$10 -> 0.35792367
D12: Hoplite (FBG) 14xx | F12: =$S12*F$4/SUM($F$4:$R$4) -> 4520.8462 | G12: =$S12*G$4/SUM($F$4:$R$4) -> 4520.8462 | H12: =$S12*H$4/SUM($F$4:$R$4) -> 4520.8462 | I12: =$S12*I$4/SUM($F$4:$R$4) -> 4520.8462 | J12: =$S12*J$4/SUM($F$4:$R$4) -> 4520.8462 | K12: =$S12*K$4/SUM($F$4:$R$4) -> 4520.8462 | L12: =$S12*L$4/SUM($F$4:$R$4) -> 4520.8462 | M12: =$S12*M$4/SUM($F$4:$R$4) -> 4520.8462 | ... R12: =$S12*R$4/SUM($F$4:$R$4) -> 4520.8462 | S12: ='[64]Main Demand SOP'!I42 -> 58771 | T12: =$AG12*T$4/SUM($T$4:$AF$4) -> 4601.2308 | U12: =$AG12*U$4/SUM($T$4:$AF$4) -> 4601.2308 | V12: =$AG12*V$4/SUM($T$4:$AF$4) -> 4601.2308 | W12: =$AG12*W$4/SUM($T$4:$AF$4) -> 4601.2308 | X12: =$AG12*X$4/SUM($T$4:$AF$4) -> 4601.2308 | Y12: =$AG12*Y$4/SUM($T$4:$AF$4) -> 4601.2308 | Z12: =$AG12*Z$4/SUM($T$4:$AF$4) -> 4601.2308 | AA12: =$AG12*AA$4/SUM($T$4:$AF$4) -> 4601.2308 | ... AF12: =$AG12*AF$4/SUM($T$4:$AF$4) -> 4601.2308 | AG12: ='[64]Main Demand SOP'!J42 -> 59816 | AH12: =$AU12*AH$4/SUM($AH$4:$AT$4) -> 9226.8462 | AI12: =$AU12*AI$4/SUM($AH$4:$AT$4) -> 9226.8462 | AJ12: =$AU12*AJ$4/SUM($AH$4:$AT$4) -> 9226.8462 | AK12: =$AU12*AK$4/SUM($AH$4:$AT$4) -> 9226.8462 | AL12: =$AU12*AL$4/SUM($AH$4:$AT$4) -> 9226.8462 | AM12: =$AU12*AM$4/SUM($AH$4:$AT$4) -> 9226.8462 | AN12: =$AU12*AN$4/SUM($AH$4:$AT$4) -> 9226.8462 | AO12: =$AU12*AO$4/SUM($AH$4:$AT$4) -> 9226.8462 | ... AT12: =$AU12*AT$4/SUM($AH$4:$AT$4) -> 9226.8462 | AU12: ='[64]Main Demand SOP'!K42 -> 119949 | AV12: =$BL12*AV$4/SUM($AH$4:$AT$4) -> 10552.846 | AW12: =$BL12*AW$4/SUM($AH$4:$AT$4) -> 10552.846 | AX12: =$BL12*AX$4/SUM($AH$4:$AT$4) -> 10552.846 | AY12: =$BL12*AY$4/SUM($AH$4:$AT$4) -> 10552.846 | AZ12: =$BL12*AZ$4/SUM($AH$4:$AT$4) -> 10552.846 | BA12: =$BL12*BA$4/SUM($AH$4:$AT$4) -> 10552.846 | BB12: =$BL12*BB$4/SUM($AH$4:$AT$4) -> 10552.846 | BC12: =$BL12*BC$4/SUM($AH$4:$AT$4) -> 10552.846 | ... BH12: =$BL12*BH$4/SUM($AH$4:$AT$4) -> 10552.846 | BI12: ='[64]Main Demand SOP'!L42 -> 117682 | BJ12: ='[64]Main Demand SOP'!M42 -> 115772 | BK12: ='[64]Main Demand SOP'!N42 -> 117725 | BL12: ='[64]Main Demand SOP'!O42 -> 137187 | BM12: ='[64]Main Demand SOP'!P42 -> 192849 | BN12: =S12/$S$10 -> 0.12126892
D13: Hoplens (FTA) 980 | F13: =$S13*F$4/SUM($F$4:$R$4) -> 12942.923 | G13: =$S13*G$4/SUM($F$4:$R$4) -> 12942.923 | H13: =$S13*H$4/SUM($F$4:$R$4) -> 12942.923 | I13: =$S13*I$4/SUM($F$4:$R$4) -> 12942.923 | J13: =$S13*J$4/SUM($F$4:$R$4) -> 12942.923 | K13: =$S13*K$4/SUM($F$4:$R$4) -> 12942.923 | L13: =$S13*L$4/SUM($F$4:$R$4) -> 12942.923 | M13: =$S13*M$4/SUM($F$4:$R$4) -> 12942.923 | ... R13: =$S13*R$4/SUM($F$4:$R$4) -> 12942.923 | S13: ='[64]Main Demand SOP'!I43 -> 168258 | T13: =$AG13*T$4/SUM($T$4:$AF$4) -> 21091.846 | U13: =$AG13*U$4/SUM($T$4:$AF$4) -> 21091.846 | V13: =$AG13*V$4/SUM($T$4:$AF$4) -> 21091.846 | W13: =$AG13*W$4/SUM($T$4:$AF$4) -> 21091.846 | X13: =$AG13*X$4/SUM($T$4:$AF$4) -> 21091.846 | Y13: =$AG13*Y$4/SUM($T$4:$AF$4) -> 21091.846 | Z13: =$AG13*Z$4/SUM($T$4:$AF$4) -> 21091.846 | AA13: =$AG13*AA$4/SUM($T$4:$AF$4) -> 21091.846 | ... AF13: =$AG13*AF$4/SUM($T$4:$AF$4) -> 21091.846 | AG13: ='[64]Main Demand SOP'!J43 -> 274194 | AH13: =$AU13*AH$4/SUM($AH$4:$AT$4) -> 51877.923 | AI13: =$AU13*AI$4/SUM($AH$4:$AT$4) -> 51877.923 | AJ13: =$AU13*AJ$4/SUM($AH$4:$AT$4) -> 51877.923 | AK13: =$AU13*AK$4/SUM($AH$4:$AT$4) -> 51877.923 | AL13: =$AU13*AL$4/SUM($AH$4:$AT$4) -> 51877.923 | AM13: =$AU13*AM$4/SUM($AH$4:$AT$4) -> 51877.923 | AN13: =$AU13*AN$4/SUM($AH$4:$AT$4) -> 51877.923 | AO13: =$AU13*AO$4/SUM($AH$4:$AT$4) -> 51877.923 | ... AT13: =$AU13*AT$4/SUM($AH$4:$AT$4) -> 51877.923 | AU13: ='[64]Main Demand SOP'!K43 -> 674413 | AV13: =$BL13*AV$4/SUM($AH$4:$AT$4) -> 33841.308 | AW13: =$BL13*AW$4/SUM($AH$4:$AT$4) -> 33841.308 | AX13: =$BL13*AX$4/SUM($AH$4:$AT$4) -> 33841.308 | AY13: =$BL13*AY$4/SUM($AH$4:$AT$4) -> 33841.308 | AZ13: =$BL13*AZ$4/SUM($AH$4:$AT$4) -> 33841.308 | BA13: =$BL13*BA$4/SUM($AH$4:$AT$4) -> 33841.308 | BB13: =$BL13*BB$4/SUM($AH$4:$AT$4) -> 33841.308 | BC13: =$BL13*BC$4/SUM($AH$4:$AT$4) -> 33841.308 | ... BH13: =$BL13*BH$4/SUM($AH$4:$AT$4) -> 33841.308 | BI13: ='[64]Main Demand SOP'!L43 -> 372022 | BJ13: ='[64]Main Demand SOP'!M43 -> 448641 | BK13: ='[64]Main Demand SOP'!N43 -> 446221 | BL13: ='[64]Main Demand SOP'!O43 -> 439937 | BM13: ='[64]Main Demand SOP'!P43 -> 438828 | BN13: =S13/$S$10 -> 0.34718596
D14: Hoplens (FLA) 14xx | F14: =$S14*F$4/SUM($F$4:$R$4) -> 4861.9231 | G14: =$S14*G$4/SUM($F$4:$R$4) -> 4861.9231 | H14: =$S14*H$4/SUM($F$4:$R$4) -> 4861.9231 | I14: =$S14*I$4/SUM($F$4:$R$4) -> 4861.9231 | J14: =$S14*J$4/SUM($F$4:$R$4) -> 4861.9231 | K14: =$S14*K$4/SUM($F$4:$R$4) -> 4861.9231 | L14: =$S14*L$4/SUM($F$4:$R$4) -> 4861.9231 | M14: =$S14*M$4/SUM($F$4:$R$4) -> 4861.9231 | ... R14: =$S14*R$4/SUM($F$4:$R$4) -> 4861.9231 | S14: ='[64]Main Demand SOP'!I44 -> 63205 | T14: =$AG14*T$4/SUM($T$4:$AF$4) -> 4948.7692 | U14: =$AG14*U$4/SUM($T$4:$AF$4) -> 4948.7692 | V14: =$AG14*V$4/SUM($T$4:$AF$4) -> 4948.7692 | W14: =$AG14*W$4/SUM($T$4:$AF$4) -> 4948.7692 | X14: =$AG14*X$4/SUM($T$4:$AF$4) -> 4948.7692 | Y14: =$AG14*Y$4/SUM($T$4:$AF$4) -> 4948.7692 | Z14: =$AG14*Z$4/SUM($T$4:$AF$4) -> 4948.7692 | AA14: =$AG14*AA$4/SUM($T$4:$AF$4) -> 4948.7692 | ... AF14: =$AG14*AF$4/SUM($T$4:$AF$4) -> 4948.7692 | AG14: ='[64]Main Demand SOP'!J44 -> 64334 | AH14: =$AU14*AH$4/SUM($AH$4:$AT$4) -> 9921.9231 | AI14: =$AU14*AI$4/SUM($AH$4:$AT$4) -> 9921.9231 | AJ14: =$AU14*AJ$4/SUM($AH$4:$AT$4) -> 9921.9231 | AK14: =$AU14*AK$4/SUM($AH$4:$AT$4) -> 9921.9231 | AL14: =$AU14*AL$4/SUM($AH$4:$AT$4) -> 9921.9231 | AM14: =$AU14*AM$4/SUM($AH$4:$AT$4) -> 9921.9231 | AN14: =$AU14*AN$4/SUM($AH$4:$AT$4) -> 9921.9231 | AO14: =$AU14*AO$4/SUM($AH$4:$AT$4) -> 9921.9231 | ... AT14: =$AU14*AT$4/SUM($AH$4:$AT$4) -> 9921.9231 | AU14: ='[64]Main Demand SOP'!K44 -> 128985 | AV14: =$BL14*AV$4/SUM($AH$4:$AT$4) -> 11348.154 | AW14: =$BL14*AW$4/SUM($AH$4:$AT$4) -> 11348.154 | AX14: =$BL14*AX$4/SUM($AH$4:$AT$4) -> 11348.154 | AY14: =$BL14*AY$4/SUM($AH$4:$AT$4) -> 11348.154 | AZ14: =$BL14*AZ$4/SUM($AH$4:$AT$4) -> 11348.154 | BA14: =$BL14*BA$4/SUM($AH$4:$AT$4) -> 11348.154 | BB14: =$BL14*BB$4/SUM($AH$4:$AT$4) -> 11348.154 | BC14: =$BL14*BC$4/SUM($AH$4:$AT$4) -> 11348.154 | ... BH14: =$BL14*BH$4/SUM($AH$4:$AT$4) -> 11348.154 | BI14: ='[64]Main Demand SOP'!L44 -> 126563 | BJ14: ='[64]Main Demand SOP'!M44 -> 124480 | BK14: ='[64]Main Demand SOP'!N44 -> 126582 | BL14: ='[64]Main Demand SOP'!O44 -> 147526 | BM14: ='[64]Main Demand SOP'!P44 -> 207427 | BN14: =S14/$S$10 -> 0.1304181
D15: Hoplens (FTA) H1x | F15: =$S15*F$4/SUM($F$4:$R$4) -> 1268.1538 | G15: =$S15*G$4/SUM($F$4:$R$4) -> 1268.1538 | H15: =$S15*H$4/SUM($F$4:$R$4) -> 1268.1538 | I15: =$S15*I$4/SUM($F$4:$R$4) -> 1268.1538 | J15: =$S15*J$4/SUM($F$4:$R$4) -> 1268.1538 | K15: =$S15*K$4/SUM($F$4:$R$4) -> 1268.1538 | L15: =$S15*L$4/SUM($F$4:$R$4) -> 1268.1538 | M15: =$S15*M$4/SUM($F$4:$R$4) -> 1268.1538 | ... R15: =$S15*R$4/SUM($F$4:$R$4) -> 1268.1538 | S15: ='[64]Main Demand SOP'!I45 -> 16486 | T15: =$AG15*T$4/SUM($T$4:$AF$4) -> 2617.3077 | U15: =$AG15*U$4/SUM($T$4:$AF$4) -> 2617.3077 | V15: =$AG15*V$4/SUM($T$4:$AF$4) -> 2617.3077 | W15: =$AG15*W$4/SUM($T$4:$AF$4) -> 2617.3077 | X15: =$AG15*X$4/SUM($T$4:$AF$4) -> 2617.3077 | Y15: =$AG15*Y$4/SUM($T$4:$AF$4) -> 2617.3077 | Z15: =$AG15*Z$4/SUM($T$4:$AF$4) -> 2617.3077 | AA15: =$AG15*AA$4/SUM($T$4:$AF$4) -> 2617.3077 | ... AF15: =$AG15*AF$4/SUM($T$4:$AF$4) -> 2617.3077 | AG15: ='[64]Main Demand SOP'!J45 -> 34025 | AH15: =$AU15*AH$4/SUM($AH$4:$AT$4) -> 7487.3846 | AI15: =$AU15*AI$4/SUM($AH$4:$AT$4) -> 7487.3846 | AJ15: =$AU15*AJ$4/SUM($AH$4:$AT$4) -> 7487.3846 | AK15: =$AU15*AK$4/SUM($AH$4:$AT$4) -> 7487.3846 | AL15: =$AU15*AL$4/SUM($AH$4:$AT$4) -> 7487.3846 | AM15: =$AU15*AM$4/SUM($AH$4:$AT$4) -> 7487.3846 | AN15: =$AU15*AN$4/SUM($AH$4:$AT$4) -> 7487.3846 | AO15: =$AU15*AO$4/SUM($AH$4:$AT$4) -> 7487.3846 | ... AT15: =$AU15*AT$4/SUM($AH$4:$AT$4) -> 7487.3846 | AU15: ='[64]Main Demand SOP'!K45 -> 97336 | AV15: =$BL15*AV$4/SUM($AH$4:$AT$4) -> 10462.231 | AW15: =$BL15*AW$4/SUM($AH$4:$AT$4) -> 10462.231 | AX15: =$BL15*AX$4/SUM($AH$4:$AT$4) -> 10462.231 | AY15: =$BL15*AY$4/SUM($AH$4:$AT$4) -> 10462.231 | AZ15: =$BL15*AZ$4/SUM($AH$4:$AT$4) -> 10462.231 | BA15: =$BL15*BA$4/SUM($AH$4:$AT$4) -> 10462.231 | BB15: =$BL15*BB$4/SUM($AH$4:$AT$4) -> 10462.231 | BC15: =$BL15*BC$4/SUM($AH$4:$AT$4) -> 10462.231 | ... BH15: =$BL15*BH$4/SUM($AH$4:$AT$4) -> 10462.231 | BI15: ='[64]Main Demand SOP'!L45 -> 166122 | BJ15: ='[64]Main Demand SOP'!M45 -> 142822 | BK15: ='[64]Main Demand SOP'!N45 -> 140746 | BL15: ='[64]Main Demand SOP'!O45 -> 136009 | BM15: ='[64]Main Demand SOP'!P45 -> 136885 | BN15: =S15/$S$10 -> 0.034017448
D16: (FBG/FLA) 14xx Turn-Key
D17: Hoplite | F17: =SUM(F11:F12) -> 17864.066 | G17: =SUM(G11:G12) -> 17864.066 | H17: =SUM(H11:H12) -> 17864.066 | I17: =SUM(I11:I12) -> 17864.066 | J17: =SUM(J11:J12) -> 17864.066 | K17: =SUM(K11:K12) -> 17864.066 | L17: =SUM(L11:L12) -> 17864.066 | M17: =SUM(M11:M12) -> 17864.066 | ... AG17: =SUM(AG11:AG12) -> 342490.23 | AU17: =SUM(AU11:AU12) -> 815220.13 | BI17: =SUM(BI11:BI12) -> 501209.84 | BJ17: =SUM(BJ11:BJ12) -> 578288.49 | BK17: =SUM(BK11:BK12) -> 577746.65 | BL17: =SUM(BL11:BL12) -> 590730.3 | BM17: =SUM(BM11:BM12) -> 645249
D18: Hoplens | F18: =SUM(F13:F15) -> 19073 | G18: =SUM(G13:G15) -> 19073 | H18: =SUM(H13:H15) -> 19073 | I18: =SUM(I13:I15) -> 19073 | J18: =SUM(J13:J15) -> 19073 | K18: =SUM(K13:K15) -> 19073 | L18: =SUM(L13:L15) -> 19073 | M18: =SUM(M13:M15) -> 19073 | ... AG18: =SUM(AG13:AG15) -> 372553 | AU18: =SUM(AU13:AU15) -> 900734 | BI18: =SUM(BI13:BI15) -> 664707 | BJ18: =SUM(BJ13:BJ15) -> 715943 | BK18: =SUM(BK13:BK15) -> 713549 | BL18: =SUM(BL13:BL15) -> 723472 | BM18: =SUM(BM13:BM15) -> 783140
D19: Total HLHL | S19: =SUM(S12:S15) -> 306720 | AG19: =SUM(AG12:AG15) -> 432369 | AU19: =SUM(AU12:AU15) -> 1020683 | BI19: =SUM(BI12:BI15) -> 782389 | BJ19: =SUM(BJ12:BJ15) -> 831715 | BK19: =SUM(BK12:BK15) -> 831274 | BL19: =SUM(BL12:BL15) -> 860659 | BM19: =SUM(BM12:BM15) -> 975989
D20: Hoplite (FBG) HRS | F20: =$S20*F$4/SUM($F$4:$R$4) -> 173.83029 | G20: =$S20*G$4/SUM($F$4:$R$4) -> 173.83029 | H20: =$S20*H$4/SUM($F$4:$R$4) -> 173.83029 | I20: =$S20*I$4/SUM($F$4:$R$4) -> 173.83029 | J20: =$S20*J$4/SUM($F$4:$R$4) -> 173.83029 | K20: =$S20*K$4/SUM($F$4:$R$4) -> 173.83029 | L20: =$S20*L$4/SUM($F$4:$R$4) -> 173.83029 | M20: =$S20*M$4/SUM($F$4:$R$4) -> 173.83029 | ... R20: =$S20*R$4/SUM($F$4:$R$4) -> 173.83029 | S20: =S21/0.97 -> 2259.7938 | T20: =$AG20*T$4/SUM($T$4:$AF$4) -> 191.27676 | U20: =$AG20*U$4/SUM($T$4:$AF$4) -> 191.27676 | V20: =$AG20*V$4/SUM($T$4:$AF$4) -> 191.27676 | W20: =$AG20*W$4/SUM($T$4:$AF$4) -> 191.27676 | X20: =$AG20*X$4/SUM($T$4:$AF$4) -> 191.27676 | Y20: =$AG20*Y$4/SUM($T$4:$AF$4) -> 191.27676 | Z20: =$AG20*Z$4/SUM($T$4:$AF$4) -> 191.27676 | AA20: =$AG20*AA$4/SUM($T$4:$AF$4) -> 191.27676 | ... AF20: =$AG20*AF$4/SUM($T$4:$AF$4) -> 191.27676 | AG20: =AG21/0.97 -> 2486.5979 | AH20: =$AU20*AH$4/SUM($AH$4:$AT$4) -> 112.29183 | AI20: =$AU20*AI$4/SUM($AH$4:$AT$4) -> 112.29183 | AJ20: =$AU20*AJ$4/SUM($AH$4:$AT$4) -> 112.29183 | AK20: =$AU20*AK$4/SUM($AH$4:$AT$4) -> 112.29183 | AL20: =$AU20*AL$4/SUM($AH$4:$AT$4) -> 112.29183 | AM20: =$AU20*AM$4/SUM($AH$4:$AT$4) -> 112.29183 | AN20: =$AU20*AN$4/SUM($AH$4:$AT$4) -> 112.29183 | AO20: =$AU20*AO$4/SUM($AH$4:$AT$4) -> 112.29183 | ... AT20: =$AU20*AT$4/SUM($AH$4:$AT$4) -> 112.29183 | AU20: =AU21/0.97 -> 1459.7938 | AV20: =$AU20*AV$4/SUM($AH$4:$AT$4) -> 112.29183 | AW20: =$AU20*AW$4/SUM($AH$4:$AT$4) -> 112.29183 | AX20: =$AU20*AX$4/SUM($AH$4:$AT$4) -> 112.29183 | AY20: =$AU20*AY$4/SUM($AH$4:$AT$4) -> 112.29183 | AZ20: =$AU20*AZ$4/SUM($AH$4:$AT$4) -> 112.29183 | BA20: =$AU20*BA$4/SUM($AH$4:$AT$4) -> 112.29183 | BB20: =$AU20*BB$4/SUM($AH$4:$AT$4) -> 112.29183 | BC20: =$AU20*BC$4/SUM($AH$4:$AT$4) -> 112.29183 | ... BH20: =$AU20*BH$4/SUM($AH$4:$AT$4) -> 112.29183 | BI20: =BI21/0.97 -> 1837.1134 | BJ20: =BJ21/0.97 -> 3216.4948 | BK20: =BK21/0.97 -> 3216.4948 | BL20: =BL21/0.97 -> 3216.4948 | BM20: =BM21/0.97 -> 3216.4948
D21: Hoplens (FTA) HRS | F21: =$S21*F$4/SUM($F$4:$R$4) -> 168.61538 | G21: =$S21*G$4/SUM($F$4:$R$4) -> 168.61538 | H21: =$S21*H$4/SUM($F$4:$R$4) -> 168.61538 | I21: =$S21*I$4/SUM($F$4:$R$4) -> 168.61538 | J21: =$S21*J$4/SUM($F$4:$R$4) -> 168.61538 | K21: =$S21*K$4/SUM($F$4:$R$4) -> 168.61538 | L21: =$S21*L$4/SUM($F$4:$R$4) -> 168.61538 | M21: =$S21*M$4/SUM($F$4:$R$4) -> 168.61538 | ... R21: =$S21*R$4/SUM($F$4:$R$4) -> 168.61538 | S21: 2192 | T21: =$AG21*T$4/SUM($T$4:$AF$4) -> 185.53846 | U21: =$AG21*U$4/SUM($T$4:$AF$4) -> 185.53846 | V21: =$AG21*V$4/SUM($T$4:$AF$4) -> 185.53846 | W21: =$AG21*W$4/SUM($T$4:$AF$4) -> 185.53846 | X21: =$AG21*X$4/SUM($T$4:$AF$4) -> 185.53846 | Y21: =$AG21*Y$4/SUM($T$4:$AF$4) -> 185.53846 | Z21: =$AG21*Z$4/SUM($T$4:$AF$4) -> 185.53846 | AA21: =$AG21*AA$4/SUM($T$4:$AF$4) -> 185.53846 | ... AF21: =$AG21*AF$4/SUM($T$4:$AF$4) -> 185.53846 | AG21: 2412 | AH21: =$AU21*AH$4/SUM($AH$4:$AT$4) -> 108.92308 | AI21: =$AU21*AI$4/SUM($AH$4:$AT$4) -> 108.92308 | AJ21: =$AU21*AJ$4/SUM($AH$4:$AT$4) -> 108.92308 | AK21: =$AU21*AK$4/SUM($AH$4:$AT$4) -> 108.92308 | AL21: =$AU21*AL$4/SUM($AH$4:$AT$4) -> 108.92308 | AM21: =$AU21*AM$4/SUM($AH$4:$AT$4) -> 108.92308 | AN21: =$AU21*AN$4/SUM($AH$4:$AT$4) -> 108.92308 | AO21: =$AU21*AO$4/SUM($AH$4:$AT$4) -> 108.92308 | ... AT21: =$AU21*AT$4/SUM($AH$4:$AT$4) -> 108.92308 | AU21: 1416 | AV21: =$AU21*AV$4/SUM($AH$4:$AT$4) -> 108.92308 | AW21: =$AU21*AW$4/SUM($AH$4:$AT$4) -> 108.92308 | AX21: =$AU21*AX$4/SUM($AH$4:$AT$4) -> 108.92308 | AY21: =$AU21*AY$4/SUM($AH$4:$AT$4) -> 108.92308 | AZ21: =$AU21*AZ$4/SUM($AH$4:$AT$4) -> 108.92308 | BA21: =$AU21*BA$4/SUM($AH$4:$AT$4) -> 108.92308 | BB21: =$AU21*BB$4/SUM($AH$4:$AT$4) -> 108.92308 | BC21: =$AU21*BC$4/SUM($AH$4:$AT$4) -> 108.92308 | ... BH21: =$AU21*BH$4/SUM($AH$4:$AT$4) -> 108.92308 | BI21: 1782 | BJ21: 3120 | BK21: 3120 | BL21: 3120 | BM21: 3120
D22: HRS | F22: =SUM(F20:F21) -> 342.44568 | G22: =SUM(G20:G21) -> 342.44568 | H22: =SUM(H20:H21) -> 342.44568 | I22: =SUM(I20:I21) -> 342.44568 | J22: =SUM(J20:J21) -> 342.44568 | K22: =SUM(K20:K21) -> 342.44568 | L22: =SUM(L20:L21) -> 342.44568 | M22: =SUM(M20:M21) -> 342.44568 | ... AG22: =SUM(AG20:AG21) -> 4898.5979 | AU22: =SUM(AU20:AU21) -> 2875.7938 | BI22: =SUM(BI20:BI21) -> 3619.1134 | BJ22: =SUM(BJ20:BJ21) -> 6336.4948 | BK22: =SUM(BK20:BK21) -> 6336.4948 | BL22: =SUM(BL20:BL21) -> 6336.4948 | BM22: =SUM(BM20:BM21) -> 6336.4948
D23: Capacity target
D24: Total build plan | F24: =$S24*F$4/SUM($F$4:$R$4) -> 35649.08 | G24: =$S24*G$4/SUM($F$4:$R$4) -> 35649.08 | H24: =$S24*H$4/SUM($F$4:$R$4) -> 35649.08 | I24: =$S24*I$4/SUM($F$4:$R$4) -> 35649.08 | J24: =$S24*J$4/SUM($F$4:$R$4) -> 35649.08 | K24: =$S24*K$4/SUM($F$4:$R$4) -> 35649.08 | L24: =$S24*L$4/SUM($F$4:$R$4) -> 35649.08 | M24: =$S24*M$4/SUM($F$4:$R$4) -> 35649.08 | ... R24: =$S24*R$4/SUM($F$4:$R$4) -> 35649.08 | S24: =SUM(S25:S29,S34:S35) -> 463438.05 | T24: =$AG24*T$4/SUM($T$4:$AF$4) -> 53763.214 | U24: =$AG24*U$4/SUM($T$4:$AF$4) -> 53763.214 | V24: =$AG24*V$4/SUM($T$4:$AF$4) -> 53763.214 | W24: =$AG24*W$4/SUM($T$4:$AF$4) -> 53763.214 | X24: =$AG24*X$4/SUM($T$4:$AF$4) -> 53763.214 | Y24: =$AG24*Y$4/SUM($T$4:$AF$4) -> 53763.214 | Z24: =$AG24*Z$4/SUM($T$4:$AF$4) -> 53763.214 | AA24: =$AG24*AA$4/SUM($T$4:$AF$4) -> 53763.214 | ... AF24: =$AG24*AF$4/SUM($T$4:$AF$4) -> 53763.214 | AG24: =SUM(AG25:AG29,AG34:AG35) -> 698921.78 | AH24: =$AG24*AH$4/SUM($T$4:$AF$4) -> 53763.214 | AI24: =$AG24*AI$4/SUM($T$4:$AF$4) -> 53763.214 | AJ24: =$AG24*AJ$4/SUM($T$4:$AF$4) -> 53763.214 | AK24: =$AG24*AK$4/SUM($T$4:$AF$4) -> 53763.214 | AL24: =$AG24*AL$4/SUM($T$4:$AF$4) -> 53763.214 | AM24: =$AG24*AM$4/SUM($T$4:$AF$4) -> 53763.214 | AN24: =$AG24*AN$4/SUM($T$4:$AF$4) -> 53763.214 | AO24: =$AG24*AO$4/SUM($T$4:$AF$4) -> 53763.214 | ... AT24: =$AG24*AT$4/SUM($T$4:$AF$4) -> 53763.214 | AU24: =SUM(AU25:AU29,AU34:AU35) -> 710103.73 | AV24: =$AG24*AV$4/SUM($T$4:$AF$4) -> 53763.214 | AW24: =$AG24*AW$4/SUM($T$4:$AF$4) -> 53763.214 | AX24: =$AG24*AX$4/SUM($T$4:$AF$4) -> 53763.214 | AY24: =$AG24*AY$4/SUM($T$4:$AF$4) -> 53763.214 | AZ24: =$AG24*AZ$4/SUM($T$4:$AF$4) -> 53763.214 | BA24: =$AG24*BA$4/SUM($T$4:$AF$4) -> 53763.214 | BB24: =$AG24*BB$4/SUM($T$4:$AF$4) -> 53763.214 | BC24: =$AG24*BC$4/SUM($T$4:$AF$4) -> 53763.214 | ... BH24: =$AG24*BH$4/SUM($T$4:$AF$4) -> 53763.214 | BI24: =SUM(BI25:BI29,BI34:BI35) -> 820495.31 | BJ24: =SUM(BJ25:BJ29,BJ34:BJ35) -> 823212.7 | BK24: =SUM(BK25:BK29,BK34:BK35) -> 823212.7 | BL24: =SUM(BL25:BL29,BL34:BL35) -> 823212.7 | BM24: =SUM(BM25:BM29,BM34:BM35) -> 823212.7 | BO24: ='[64]Capacity target details'!L24 -> Sim 343K (New mix)
D25: Hoplite (FBG) 980 | F25: =$S25*F$4/SUM($F$4:$R$4) -> 12623.865 | G25: =$S25*G$4/SUM($F$4:$R$4) -> 12623.865 | H25: =$S25*H$4/SUM($F$4:$R$4) -> 12623.865 | I25: =$S25*I$4/SUM($F$4:$R$4) -> 12623.865 | J25: =$S25*J$4/SUM($F$4:$R$4) -> 12623.865 | K25: =$S25*K$4/SUM($F$4:$R$4) -> 12623.865 | L25: =$S25*L$4/SUM($F$4:$R$4) -> 12623.865 | M25: =$S25*M$4/SUM($F$4:$R$4) -> 12623.865 | ... R25: =$S25*R$4/SUM($F$4:$R$4) -> 12623.865 | S25: 164110.25 | T25: =$AG25*T$4/SUM($T$4:$AF$4) -> 20608.168 | U25: =$AG25*U$4/SUM($T$4:$AF$4) -> 20608.168 | V25: =$AG25*V$4/SUM($T$4:$AF$4) -> 20608.168 | W25: =$AG25*W$4/SUM($T$4:$AF$4) -> 20608.168 | X25: =$AG25*X$4/SUM($T$4:$AF$4) -> 20608.168 | Y25: =$AG25*Y$4/SUM($T$4:$AF$4) -> 20608.168 | Z25: =$AG25*Z$4/SUM($T$4:$AF$4) -> 20608.168 | AA25: =$AG25*AA$4/SUM($T$4:$AF$4) -> 20608.168 | ... AF25: =$AG25*AF$4/SUM($T$4:$AF$4) -> 20608.168 | AG25: =AG27/0.97 -> 267906.19 | AH25: =$AU25*AH$4/SUM($AH$4:$AT$4) -> 21139.122 | AI25: =$AU25*AI$4/SUM($AH$4:$AT$4) -> 21139.122 | AJ25: =$AU25*AJ$4/SUM($AH$4:$AT$4) -> 21139.122 | AK25: =$AU25*AK$4/SUM($AH$4:$AT$4) -> 21139.122 | AL25: =$AU25*AL$4/SUM($AH$4:$AT$4) -> 21139.122 | AM25: =$AU25*AM$4/SUM($AH$4:$AT$4) -> 21139.122 | AN25: =$AU25*AN$4/SUM($AH$4:$AT$4) -> 21139.122 | AO25: =$AU25*AO$4/SUM($AH$4:$AT$4) -> 21139.122 | ... AT25: =$AU25*AT$4/SUM($AH$4:$AT$4) -> 21139.122 | AU25: 274808.59 | AV25: =$AU25*AV$4/SUM($AH$4:$AT$4) -> 21139.122 | AW25: =$AU25*AW$4/SUM($AH$4:$AT$4) -> 21139.122 | AX25: =$AU25*AX$4/SUM($AH$4:$AT$4) -> 21139.122 | AY25: =$AU25*AY$4/SUM($AH$4:$AT$4) -> 21139.122 | AZ25: =$AU25*AZ$4/SUM($AH$4:$AT$4) -> 21139.122 | BA25: =$AU25*BA$4/SUM($AH$4:$AT$4) -> 21139.122 | BB25: =$AU25*BB$4/SUM($AH$4:$AT$4) -> 21139.122 | BC25: =$AU25*BC$4/SUM($AH$4:$AT$4) -> 21139.122 | ... BH25: =$AU25*BH$4/SUM($AH$4:$AT$4) -> 21139.122 | BI25: ='[64]Capacity target details'!J25 -> 274808.59 | BJ25: =BI25 -> 274808.59 | BK25: =BJ25 -> 274808.59 | BL25: =BK25 -> 274808.59 | BM25: =BL25 -> 274808.59 | BO25: ='[64]Capacity target details'!L25 -> 355112.37
D26: Hoplite (FBG) 14xx | F26: =$S26*F$4/SUM($F$4:$R$4) -> 4520.8462 | G26: =$S26*G$4/SUM($F$4:$R$4) -> 4520.8462 | H26: =$S26*H$4/SUM($F$4:$R$4) -> 4520.8462 | I26: =$S26*I$4/SUM($F$4:$R$4) -> 4520.8462 | J26: =$S26*J$4/SUM($F$4:$R$4) -> 4520.8462 | K26: =$S26*K$4/SUM($F$4:$R$4) -> 4520.8462 | L26: =$S26*L$4/SUM($F$4:$R$4) -> 4520.8462 | M26: =$S26*M$4/SUM($F$4:$R$4) -> 4520.8462 | ... R26: =$S26*R$4/SUM($F$4:$R$4) -> 4520.8462 | S26: =S12 -> 58771 | T26: =$AG26*T$4/SUM($T$4:$AF$4) -> 5608.3077 | U26: =$AG26*U$4/SUM($T$4:$AF$4) -> 5608.3077 | V26: =$AG26*V$4/SUM($T$4:$AF$4) -> 5608.3077 | W26: =$AG26*W$4/SUM($T$4:$AF$4) -> 5608.3077 | X26: =$AG26*X$4/SUM($T$4:$AF$4) -> 5608.3077 | Y26: =$AG26*Y$4/SUM($T$4:$AF$4) -> 5608.3077 | Z26: =$AG26*Z$4/SUM($T$4:$AF$4) -> 5608.3077 | AA26: =$AG26*AA$4/SUM($T$4:$AF$4) -> 5608.3077 | ... AF26: =$AG26*AF$4/SUM($T$4:$AF$4) -> 5608.3077 | AG26: 72908 | AH26: =$AU26*AH$4/SUM($AH$4:$AT$4) -> 5880.6965 | AI26: =$AU26*AI$4/SUM($AH$4:$AT$4) -> 5880.6965 | AJ26: =$AU26*AJ$4/SUM($AH$4:$AT$4) -> 5880.6965 | AK26: =$AU26*AK$4/SUM($AH$4:$AT$4) -> 5880.6965 | AL26: =$AU26*AL$4/SUM($AH$4:$AT$4) -> 5880.6965 | AM26: =$AU26*AM$4/SUM($AH$4:$AT$4) -> 5880.6965 | AN26: =$AU26*AN$4/SUM($AH$4:$AT$4) -> 5880.6965 | AO26: =$AU26*AO$4/SUM($AH$4:$AT$4) -> 5880.6965 | ... AT26: =$AU26*AT$4/SUM($AH$4:$AT$4) -> 5880.6965 | AU26: 76449.055 | AV26: =$AU26*AV$4/SUM($AH$4:$AT$4) -> 5880.6965 | AW26: =$AU26*AW$4/SUM($AH$4:$AT$4) -> 5880.6965 | AX26: =$AU26*AX$4/SUM($AH$4:$AT$4) -> 5880.6965 | AY26: =$AU26*AY$4/SUM($AH$4:$AT$4) -> 5880.6965 | AZ26: =$AU26*AZ$4/SUM($AH$4:$AT$4) -> 5880.6965 | BA26: =$AU26*BA$4/SUM($AH$4:$AT$4) -> 5880.6965 | BB26: =$AU26*BB$4/SUM($AH$4:$AT$4) -> 5880.6965 | BC26: =$AU26*BC$4/SUM($AH$4:$AT$4) -> 5880.6965 | ... BH26: =$AU26*BH$4/SUM($AH$4:$AT$4) -> 5880.6965 | BI26: ='[64]Capacity target details'!J26 -> 76449.055 | BJ26: =BI26 -> 76449.055 | BK26: =BJ26 -> 76449.055 | BL26: =BK26 -> 76449.055 | BM26: =BL26 -> 76449.055 | BO26: ='[64]Capacity target details'!L26 -> 88889
D27: Hoplens (FTA) 980 | F27: =$S27*F$4/SUM($F$4:$R$4) -> 12244 | G27: =$S27*G$4/SUM($F$4:$R$4) -> 12244 | H27: =$S27*H$4/SUM($F$4:$R$4) -> 12244 | I27: =$S27*I$4/SUM($F$4:$R$4) -> 12244 | J27: =$S27*J$4/SUM($F$4:$R$4) -> 12244 | K27: =$S27*K$4/SUM($F$4:$R$4) -> 12244 | L27: =$S27*L$4/SUM($F$4:$R$4) -> 12244 | M27: =$S27*M$4/SUM($F$4:$R$4) -> 12244 | ... R27: =$S27*R$4/SUM($F$4:$R$4) -> 12244 | S27: 159172 | T27: =$AG27*T$4/SUM($T$4:$AF$4) -> 19989.923 | U27: =$AG27*U$4/SUM($T$4:$AF$4) -> 19989.923 | V27: =$AG27*V$4/SUM($T$4:$AF$4) -> 19989.923 | W27: =$AG27*W$4/SUM($T$4:$AF$4) -> 19989.923 | X27: =$AG27*X$4/SUM($T$4:$AF$4) -> 19989.923 | Y27: =$AG27*Y$4/SUM($T$4:$AF$4) -> 19989.923 | Z27: =$AG27*Z$4/SUM($T$4:$AF$4) -> 19989.923 | AA27: =$AG27*AA$4/SUM($T$4:$AF$4) -> 19989.923 | ... AF27: =$AG27*AF$4/SUM($T$4:$AF$4) -> 19989.923 | AG27: 259869 | AH27: =$AU27*AH$4/SUM($AH$4:$AT$4) -> 20504.948 | AI27: =$AU27*AI$4/SUM($AH$4:$AT$4) -> 20504.948 | AJ27: =$AU27*AJ$4/SUM($AH$4:$AT$4) -> 20504.948 | AK27: =$AU27*AK$4/SUM($AH$4:$AT$4) -> 20504.948 | AL27: =$AU27*AL$4/SUM($AH$4:$AT$4) -> 20504.948 | AM27: =$AU27*AM$4/SUM($AH$4:$AT$4) -> 20504.948 | AN27: =$AU27*AN$4/SUM($AH$4:$AT$4) -> 20504.948 | AO27: =$AU27*AO$4/SUM($AH$4:$AT$4) -> 20504.948 | ... AT27: =$AU27*AT$4/SUM($AH$4:$AT$4) -> 20504.948 | AU27: 266564.33 | AV27: =$AU27*AV$4/SUM($AH$4:$AT$4) -> 20504.948 | AW27: =$AU27*AW$4/SUM($AH$4:$AT$4) -> 20504.948 | AX27: =$AU27*AX$4/SUM($AH$4:$AT$4) -> 20504.948 | AY27: =$AU27*AY$4/SUM($AH$4:$AT$4) -> 20504.948 | AZ27: =$AU27*AZ$4/SUM($AH$4:$AT$4) -> 20504.948 | BA27: =$AU27*BA$4/SUM($AH$4:$AT$4) -> 20504.948 | BB27: =$AU27*BB$4/SUM($AH$4:$AT$4) -> 20504.948 | BC27: =$AU27*BC$4/SUM($AH$4:$AT$4) -> 20504.948 | ... BH27: =$AU27*BH$4/SUM($AH$4:$AT$4) -> 20504.948 | BI27: ='[64]Capacity target details'!J27 -> 266564.33 | BJ27: =BI27 -> 266564.33 | BK27: =BJ27 -> 266564.33 | BL27: =BK27 -> 266564.33 | BM27: =BL27 -> 266564.33 | BO27: ='[64]Capacity target details'!L27 -> 344459
D28: Hoplens (FLA) 14xx | F28: =$S28*F$4/SUM($F$4:$R$4) -> 4861.9231 | G28: =$S28*G$4/SUM($F$4:$R$4) -> 4861.9231 | H28: =$S28*H$4/SUM($F$4:$R$4) -> 4861.9231 | I28: =$S28*I$4/SUM($F$4:$R$4) -> 4861.9231 | J28: =$S28*J$4/SUM($F$4:$R$4) -> 4861.9231 | K28: =$S28*K$4/SUM($F$4:$R$4) -> 4861.9231 | L28: =$S28*L$4/SUM($F$4:$R$4) -> 4861.9231 | M28: =$S28*M$4/SUM($F$4:$R$4) -> 4861.9231 | ... R28: =$S28*R$4/SUM($F$4:$R$4) -> 4861.9231 | S28: =S14 -> 63205 | T28: =$AG28*T$4/SUM($T$4:$AF$4) -> 4987.0769 | U28: =$AG28*U$4/SUM($T$4:$AF$4) -> 4987.0769 | V28: =$AG28*V$4/SUM($T$4:$AF$4) -> 4987.0769 | W28: =$AG28*W$4/SUM($T$4:$AF$4) -> 4987.0769 | X28: =$AG28*X$4/SUM($T$4:$AF$4) -> 4987.0769 | Y28: =$AG28*Y$4/SUM($T$4:$AF$4) -> 4987.0769 | Z28: =$AG28*Z$4/SUM($T$4:$AF$4) -> 4987.0769 | AA28: =$AG28*AA$4/SUM($T$4:$AF$4) -> 4987.0769 | ... AF28: =$AG28*AF$4/SUM($T$4:$AF$4) -> 4987.0769 | AG28: 64832 | AH28: =$AU28*AH$4/SUM($AH$4:$AT$4) -> 5527.8547 | AI28: =$AU28*AI$4/SUM($AH$4:$AT$4) -> 5527.8547 | AJ28: =$AU28*AJ$4/SUM($AH$4:$AT$4) -> 5527.8547 | AK28: =$AU28*AK$4/SUM($AH$4:$AT$4) -> 5527.8547 | AL28: =$AU28*AL$4/SUM($AH$4:$AT$4) -> 5527.8547 | AM28: =$AU28*AM$4/SUM($AH$4:$AT$4) -> 5527.8547 | AN28: =$AU28*AN$4/SUM($AH$4:$AT$4) -> 5527.8547 | AO28: =$AU28*AO$4/SUM($AH$4:$AT$4) -> 5527.8547 | ... AT28: =$AU28*AT$4/SUM($AH$4:$AT$4) -> 5527.8547 | AU28: 71862.111 | AV28: =$AU28*AV$4/SUM($AH$4:$AT$4) -> 5527.8547 | AW28: =$AU28*AW$4/SUM($AH$4:$AT$4) -> 5527.8547 | AX28: =$AU28*AX$4/SUM($AH$4:$AT$4) -> 5527.8547 | AY28: =$AU28*AY$4/SUM($AH$4:$AT$4) -> 5527.8547 | AZ28: =$AU28*AZ$4/SUM($AH$4:$AT$4) -> 5527.8547 | BA28: =$AU28*BA$4/SUM($AH$4:$AT$4) -> 5527.8547 | BB28: =$AU28*BB$4/SUM($AH$4:$AT$4) -> 5527.8547 | BC28: =$AU28*BC$4/SUM($AH$4:$AT$4) -> 5527.8547 | ... BH28: =$AU28*BH$4/SUM($AH$4:$AT$4) -> 5527.8547 | BI28: ='[64]Capacity target details'!J28 -> 71862.111 | BJ28: =BI28 -> 71862.111 | BK28: =BJ28 -> 71862.111 | BL28: =BK28 -> 71862.111 | BM28: =BL28 -> 71862.111 | BO28: ='[64]Capacity target details'!L28 -> 91534
D29: Hoplens (FTA) H1x | F29: =$S29*F$4/SUM($F$4:$R$4) -> 1056 | G29: =$S29*G$4/SUM($F$4:$R$4) -> 1056 | H29: =$S29*H$4/SUM($F$4:$R$4) -> 1056 | I29: =$S29*I$4/SUM($F$4:$R$4) -> 1056 | J29: =$S29*J$4/SUM($F$4:$R$4) -> 1056 | K29: =$S29*K$4/SUM($F$4:$R$4) -> 1056 | L29: =$S29*L$4/SUM($F$4:$R$4) -> 1056 | M29: =$S29*M$4/SUM($F$4:$R$4) -> 1056 | ... R29: =$S29*R$4/SUM($F$4:$R$4) -> 1056 | S29: 13728 | T29: =$AG29*T$4/SUM($T$4:$AF$4) -> 2192.9231 | U29: =$AG29*U$4/SUM($T$4:$AF$4) -> 2192.9231 | V29: =$AG29*V$4/SUM($T$4:$AF$4) -> 2192.9231 | W29: =$AG29*W$4/SUM($T$4:$AF$4) -> 2192.9231 | X29: =$AG29*X$4/SUM($T$4:$AF$4) -> 2192.9231 | Y29: =$AG29*Y$4/SUM($T$4:$AF$4) -> 2192.9231 | Z29: =$AG29*Z$4/SUM($T$4:$AF$4) -> 2192.9231 | AA29: =$AG29*AA$4/SUM($T$4:$AF$4) -> 2192.9231 | ... AF29: =$AG29*AF$4/SUM($T$4:$AF$4) -> 2192.9231 | AG29: 28508 | AH29: =$AU29*AH$4/SUM($AH$4:$AT$4) -> 1349.5277 | AI29: =$AU29*AI$4/SUM($AH$4:$AT$4) -> 1349.5277 | AJ29: =$AU29*AJ$4/SUM($AH$4:$AT$4) -> 1349.5277 | AK29: =$AU29*AK$4/SUM($AH$4:$AT$4) -> 1349.5277 | AL29: =$AU29*AL$4/SUM($AH$4:$AT$4) -> 1349.5277 | AM29: =$AU29*AM$4/SUM($AH$4:$AT$4) -> 1349.5277 | AN29: =$AU29*AN$4/SUM($AH$4:$AT$4) -> 1349.5277 | AO29: =$AU29*AO$4/SUM($AH$4:$AT$4) -> 1349.5277 | ... AT29: =$AU29*AT$4/SUM($AH$4:$AT$4) -> 1349.5277 | AU29: 17543.86 | AV29: =$AU29*AV$4/SUM($AH$4:$AT$4) -> 1349.5277 | AW29: =$AU29*AW$4/SUM($AH$4:$AT$4) -> 1349.5277 | AX29: =$AU29*AX$4/SUM($AH$4:$AT$4) -> 1349.5277 | AY29: =$AU29*AY$4/SUM($AH$4:$AT$4) -> 1349.5277 | AZ29: =$AU29*AZ$4/SUM($AH$4:$AT$4) -> 1349.5277 | BA29: =$AU29*BA$4/SUM($AH$4:$AT$4) -> 1349.5277 | BB29: =$AU29*BB$4/SUM($AH$4:$AT$4) -> 1349.5277 | BC29: =$AU29*BC$4/SUM($AH$4:$AT$4) -> 1349.5277 | ... BH29: =$AU29*BH$4/SUM($AH$4:$AT$4) -> 1349.5277 | BI29: ='[64]Capacity target details'!J29 -> 127192.12 | BJ29: =BI29 -> 127192.12 | BK29: =BJ29 -> 127192.12 | BL29: =BK29 -> 127192.12 | BM29: =BL29 -> 127192.12 | BO29: ='[64]Capacity target details'!L29 -> 25707
D30: (FBG/FLA) 14xx Turn-Key
D31: Hoplite | F31: =SUM(F25:F26) -> 17144.712 | G31: =SUM(G25:G26) -> 17144.712 | H31: =SUM(H25:H26) -> 17144.712 | I31: =SUM(I25:I26) -> 17144.712 | J31: =SUM(J25:J26) -> 17144.712 | K31: =SUM(K25:K26) -> 17144.712 | L31: =SUM(L25:L26) -> 17144.712 | M31: =SUM(M25:M26) -> 17144.712 | ... BM31: =SUM(BM25:BM26) -> 351257.64 | BO31: =SUM(BO25:BO26) -> 444001.37
D32: Hoplens | F32: =SUM(F27:F29) -> 18161.923 | G32: =SUM(G27:G29) -> 18161.923 | H32: =SUM(H27:H29) -> 18161.923 | I32: =SUM(I27:I29) -> 18161.923 | J32: =SUM(J27:J29) -> 18161.923 | K32: =SUM(K27:K29) -> 18161.923 | L32: =SUM(L27:L29) -> 18161.923 | M32: =SUM(M27:M29) -> 18161.923 | ... BM32: =SUM(BM27:BM29) -> 465618.56 | BO32: =SUM(BO27:BO29) -> 461700
D33: Total HLHL | F33: =SUM(F28:F31) -> 23062.635 | G33: =SUM(G28:G31) -> 23062.635 | H33: =SUM(H28:H31) -> 23062.635 | I33: =SUM(I28:I31) -> 23062.635 | J33: =SUM(J28:J31) -> 23062.635 | K33: =SUM(K28:K31) -> 23062.635 | L33: =SUM(L28:L31) -> 23062.635 | M33: =SUM(M28:M31) -> 23062.635 | ... R33: =SUM(R28:R31) -> 23062.635 | S33: =SUM(S26:S29) -> 294876 | T33: =SUM(T28:T31) -> 33396.476 | U33: =SUM(U28:U31) -> 33396.476 | V33: =SUM(V28:V31) -> 33396.476 | W33: =SUM(W28:W31) -> 33396.476 | X33: =SUM(X28:X31) -> 33396.476 | Y33: =SUM(Y28:Y31) -> 33396.476 | Z33: =SUM(Z28:Z31) -> 33396.476 | AA33: =SUM(AA28:AA31) -> 33396.476 | ... AF33: =SUM(AF28:AF31) -> 33396.476 | AG33: =SUM(AG26:AG29) -> 426117 | AH33: =SUM(AH28:AH31) -> 33897.201 | AI33: =SUM(AI28:AI31) -> 33897.201 | AJ33: =SUM(AJ28:AJ31) -> 33897.201 | AK33: =SUM(AK28:AK31) -> 33897.201 | AL33: =SUM(AL28:AL31) -> 33897.201 | AM33: =SUM(AM28:AM31) -> 33897.201 | AN33: =SUM(AN28:AN31) -> 33897.201 | AO33: =SUM(AO28:AO31) -> 33897.201 | ... AT33: =SUM(AT28:AT31) -> 33897.201 | AU33: =SUM(AU26:AU29) -> 432419.35 | AV33: =SUM(AV28:AV31) -> 33897.201 | AW33: =SUM(AW28:AW31) -> 33897.201 | AX33: =SUM(AX28:AX31) -> 33897.201 | AY33: =SUM(AY28:AY31) -> 33897.201 | AZ33: =SUM(AZ28:AZ31) -> 33897.201 | BA33: =SUM(BA28:BA31) -> 33897.201 | BB33: =SUM(BB28:BB31) -> 33897.201 | BC33: =SUM(BC28:BC31) -> 33897.201 | ... BH33: =SUM(BH28:BH31) -> 33897.201 | BI33: =SUM(BI26:BI29) -> 542067.62 | BJ33: =SUM(BJ26:BJ29) -> 542067.62 | BK33: =SUM(BK26:BK29) -> 542067.62 | BL33: =SUM(BL26:BL29) -> 542067.62 | BM33: =SUM(BM26:BM29) -> 542067.62 | BO33: ='[64]Capacity target details'!L31 -> 550589
D34: Hoplite (FBG) HRS | F34: =$S34*F$4/SUM($F$4:$R$4) -> 173.83029 | G34: =$S34*G$4/SUM($F$4:$R$4) -> 173.83029 | H34: =$S34*H$4/SUM($F$4:$R$4) -> 173.83029 | I34: =$S34*I$4/SUM($F$4:$R$4) -> 173.83029 | J34: =$S34*J$4/SUM($F$4:$R$4) -> 173.83029 | K34: =$S34*K$4/SUM($F$4:$R$4) -> 173.83029 | L34: =$S34*L$4/SUM($F$4:$R$4) -> 173.83029 | M34: =$S34*M$4/SUM($F$4:$R$4) -> 173.83029 | ... R34: =$S34*R$4/SUM($F$4:$R$4) -> 173.83029 | S34: =S20 -> 2259.7938 | T34: =$AG34*T$4/SUM($T$4:$AF$4) -> 191.27676 | U34: =$AG34*U$4/SUM($T$4:$AF$4) -> 191.27676 | V34: =$AG34*V$4/SUM($T$4:$AF$4) -> 191.27676 | W34: =$AG34*W$4/SUM($T$4:$AF$4) -> 191.27676 | X34: =$AG34*X$4/SUM($T$4:$AF$4) -> 191.27676 | Y34: =$AG34*Y$4/SUM($T$4:$AF$4) -> 191.27676 | Z34: =$AG34*Z$4/SUM($T$4:$AF$4) -> 191.27676 | AA34: =$AG34*AA$4/SUM($T$4:$AF$4) -> 191.27676 | ... AF34: =$AG34*AF$4/SUM($T$4:$AF$4) -> 191.27676 | AG34: =AG20 -> 2486.5979 | AH34: =$AU34*AH$4/SUM($AH$4:$AT$4) -> 112.29183 | AI34: =$AU34*AI$4/SUM($AH$4:$AT$4) -> 112.29183 | AJ34: =$AU34*AJ$4/SUM($AH$4:$AT$4) -> 112.29183 | AK34: =$AU34*AK$4/SUM($AH$4:$AT$4) -> 112.29183 | AL34: =$AU34*AL$4/SUM($AH$4:$AT$4) -> 112.29183 | AM34: =$AU34*AM$4/SUM($AH$4:$AT$4) -> 112.29183 | AN34: =$AU34*AN$4/SUM($AH$4:$AT$4) -> 112.29183 | AO34: =$AU34*AO$4/SUM($AH$4:$AT$4) -> 112.29183 | ... AT34: =$AU34*AT$4/SUM($AH$4:$AT$4) -> 112.29183 | AU34: =AU20 -> 1459.7938 | AV34: =$AU34*AV$4/SUM($AH$4:$AT$4) -> 112.29183 | AW34: =$AU34*AW$4/SUM($AH$4:$AT$4) -> 112.29183 | AX34: =$AU34*AX$4/SUM($AH$4:$AT$4) -> 112.29183 | AY34: =$AU34*AY$4/SUM($AH$4:$AT$4) -> 112.29183 | AZ34: =$AU34*AZ$4/SUM($AH$4:$AT$4) -> 112.29183 | BA34: =$AU34*BA$4/SUM($AH$4:$AT$4) -> 112.29183 | BB34: =$AU34*BB$4/SUM($AH$4:$AT$4) -> 112.29183 | BC34: =$AU34*BC$4/SUM($AH$4:$AT$4) -> 112.29183 | ... BH34: =$AU34*BH$4/SUM($AH$4:$AT$4) -> 112.29183 | BI34: =BI20 -> 1837.1134 | BJ34: =BJ20 -> 3216.4948 | BK34: =BK20 -> 3216.4948 | BL34: =BL20 -> 3216.4948 | BM34: =BM20 -> 3216.4948
D35: Hoplens (FTA) HRS | F35: =$S35*F$4/SUM($F$4:$R$4) -> 168.61538 | G35: =$S35*G$4/SUM($F$4:$R$4) -> 168.61538 | H35: =$S35*H$4/SUM($F$4:$R$4) -> 168.61538 | I35: =$S35*I$4/SUM($F$4:$R$4) -> 168.61538 | J35: =$S35*J$4/SUM($F$4:$R$4) -> 168.61538 | K35: =$S35*K$4/SUM($F$4:$R$4) -> 168.61538 | L35: =$S35*L$4/SUM($F$4:$R$4) -> 168.61538 | M35: =$S35*M$4/SUM($F$4:$R$4) -> 168.61538 | ... R35: =$S35*R$4/SUM($F$4:$R$4) -> 168.61538 | S35: =S21 -> 2192 | T35: =$AG35*T$4/SUM($T$4:$AF$4) -> 185.53846 | U35: =$AG35*U$4/SUM($T$4:$AF$4) -> 185.53846 | V35: =$AG35*V$4/SUM($T$4:$AF$4) -> 185.53846 | W35: =$AG35*W$4/SUM($T$4:$AF$4) -> 185.53846 | X35: =$AG35*X$4/SUM($T$4:$AF$4) -> 185.53846 | Y35: =$AG35*Y$4/SUM($T$4:$AF$4) -> 185.53846 | Z35: =$AG35*Z$4/SUM($T$4:$AF$4) -> 185.53846 | AA35: =$AG35*AA$4/SUM($T$4:$AF$4) -> 185.53846 | ... AF35: =$AG35*AF$4/SUM($T$4:$AF$4) -> 185.53846 | AG35: =AG21 -> 2412 | AH35: =$AU35*AH$4/SUM($AH$4:$AT$4) -> 108.92308 | AI35: =$AU35*AI$4/SUM($AH$4:$AT$4) -> 108.92308 | AJ35: =$AU35*AJ$4/SUM($AH$4:$AT$4) -> 108.92308 | AK35: =$AU35*AK$4/SUM($AH$4:$AT$4) -> 108.92308 | AL35: =$AU35*AL$4/SUM($AH$4:$AT$4) -> 108.92308 | AM35: =$AU35*AM$4/SUM($AH$4:$AT$4) -> 108.92308 | AN35: =$AU35*AN$4/SUM($AH$4:$AT$4) -> 108.92308 | AO35: =$AU35*AO$4/SUM($AH$4:$AT$4) -> 108.92308 | ... AT35: =$AU35*AT$4/SUM($AH$4:$AT$4) -> 108.92308 | AU35: =AU21 -> 1416 | AV35: =$AU35*AV$4/SUM($AH$4:$AT$4) -> 108.92308 | AW35: =$AU35*AW$4/SUM($AH$4:$AT$4) -> 108.92308 | AX35: =$AU35*AX$4/SUM($AH$4:$AT$4) -> 108.92308 | AY35: =$AU35*AY$4/SUM($AH$4:$AT$4) -> 108.92308 | AZ35: =$AU35*AZ$4/SUM($AH$4:$AT$4) -> 108.92308 | BA35: =$AU35*BA$4/SUM($AH$4:$AT$4) -> 108.92308 | BB35: =$AU35*BB$4/SUM($AH$4:$AT$4) -> 108.92308 | BC35: =$AU35*BC$4/SUM($AH$4:$AT$4) -> 108.92308 | ... BH35: =$AU35*BH$4/SUM($AH$4:$AT$4) -> 108.92308 | BI35: =BI21 -> 1782 | BJ35: =BJ21 -> 3120 | BK35: =BK21 -> 3120 | BL35: =BL21 -> 3120 | BM35: =BM21 -> 3120
D36: HRS | S36: =SUM(S34:S35) -> 4451.7938 | AG36: =SUM(AG34:AG35) -> 4898.5979 | AU36: =SUM(AU34:AU35) -> 2875.7938 | BI36: =SUM(BI34:BI35) -> 3619.1134 | BJ36: =SUM(BJ34:BJ35) -> 6336.4948 | BK36: =SUM(BK34:BK35) -> 6336.4948 | BL36: =SUM(BL34:BL35) -> 6336.4948 | BM36: =SUM(BM34:BM35) -> 6336.4948 | BN36: =MIN(BN34:BN35) -> 0
D38: Capacity summary
D39: Total Capacity | F39: =SUM(F40:F44,F49:F50) -> 30645.931 | G39: =SUM(G40:G44,G49:G50) -> 31498.985 | H39: =SUM(H40:H44,H49:H50) -> 33028.259 | I39: =SUM(I40:I44,I49:I50) -> 34557.533 | J39: =SUM(J40:J44,J49:J50) -> 35056.271 | K39: =SUM(K40:K44,K49:K50) -> 35056.271 | L39: =SUM(L40:L44,L49:L50) -> 35056.271 | M39: =SUM(M40:M44,M49:M50) -> 35056.271 | ... BM39: =SUM(BM40:BM44,BM49:BM50) -> 829851.99
D40: Hoplite (FBG) 980 | F40: =_xlfn.MINIFS(F$54:F$73,$D$54:$D$73,$D40) -> 13680.373 | G40: =_xlfn.MINIFS(G$54:G$73,$D$54:$D$73,$D40) -> 13720.636 | H40: =_xlfn.MINIFS(H$54:H$73,$D$54:$D$73,$D40) -> 13720.636 | I40: =_xlfn.MINIFS(I$54:I$73,$D$54:$D$73,$D40) -> 13720.636 | J40: =_xlfn.MINIFS(J$54:J$73,$D$54:$D$73,$D40) -> 13720.636 | K40: =_xlfn.MINIFS(K$54:K$73,$D$54:$D$73,$D40) -> 13720.636 | L40: =_xlfn.MINIFS(L$54:L$73,$D$54:$D$73,$D40) -> 13720.636 | M40: =_xlfn.MINIFS(M$54:M$73,$D$54:$D$73,$D40) -> 13720.636 | ... R40: =_xlfn.MINIFS(R$54:R$73,$D$54:$D$73,$D40) -> 19431.183 | S40: =MIN(_xlfn.MINIFS(S$59:S$73,$D$59:$D$73,$D40),(S$53*S25/SUM(S$25:S$29))) -> 203488.51 | T40: =MIN(_xlfn.MINIFS(T$59:T$73,$D$59:$D$73,$D40),(T$53*T25/SUM(T$25:T$29))) -> 21260.909 | U40: =MIN(_xlfn.MINIFS(U$59:U$73,$D$59:$D$73,$D40),(U$53*U25/SUM(U$25:U$29))) -> 21260.909 | V40: =MIN(_xlfn.MINIFS(V$59:V$73,$D$59:$D$73,$D40),(V$53*V25/SUM(V$25:V$29))) -> 21260.909 | W40: =MIN(_xlfn.MINIFS(W$59:W$73,$D$59:$D$73,$D40),(W$53*W25/SUM(W$25:W$29))) -> 21260.909 | X40: =MIN(_xlfn.MINIFS(X$59:X$73,$D$59:$D$73,$D40),(X$53*X25/SUM(X$25:X$29))) -> 21260.909 | Y40: =MIN(_xlfn.MINIFS(Y$59:Y$73,$D$59:$D$73,$D40),(Y$53*Y25/SUM(Y$25:Y$29))) -> 21260.909 | Z40: =MIN(_xlfn.MINIFS(Z$59:Z$73,$D$59:$D$73,$D40),(Z$53*Z25/SUM(Z$25:Z$29))) -> 21260.909 | ... BM40: =MIN(_xlfn.MINIFS(BM$59:BM$73,$D$59:$D$73,$D40),(BM$53*BM25/SUM(BM$25:BM$29))) -> 274970.06
D41: Hoplite (FBG) 14xx | F41: =_xlfn.MINIFS(F$54:F$73,$D$54:$D$73,$D41) -> 4551.7801 | G41: =_xlfn.MINIFS(G$54:G$73,$D$54:$D$73,$D41) -> 4602.0448 | H41: =_xlfn.MINIFS(H$54:H$73,$D$54:$D$73,$D41) -> 4602.0448 | I41: =_xlfn.MINIFS(I$54:I$73,$D$54:$D$73,$D41) -> 4602.0448 | J41: =_xlfn.MINIFS(J$54:J$73,$D$54:$D$73,$D41) -> 4602.0448 | K41: =_xlfn.MINIFS(K$54:K$73,$D$54:$D$73,$D41) -> 4602.0448 | L41: =_xlfn.MINIFS(L$54:L$73,$D$54:$D$73,$D41) -> 4602.0448 | M41: =_xlfn.MINIFS(M$54:M$73,$D$54:$D$73,$D41) -> 4602.0448 | ... R41: =_xlfn.MINIFS(R$54:R$73,$D$54:$D$73,$D41) -> 6958.676 | S41: =MIN(_xlfn.MINIFS(S$59:S$73,$D$59:$D$73,$D41),(S$53*S26/SUM(S$25:S$29))) -> 68110.263 | T41: =MIN(_xlfn.MINIFS(T$59:T$73,$D$59:$D$73,$D41),(T$53*T26/SUM(T$25:T$29))) -> 5785.9445 | U41: =MIN(_xlfn.MINIFS(U$59:U$73,$D$59:$D$73,$D41),(U$53*U26/SUM(U$25:U$29))) -> 5785.9445 | V41: =MIN(_xlfn.MINIFS(V$59:V$73,$D$59:$D$73,$D41),(V$53*V26/SUM(V$25:V$29))) -> 5785.9445 | W41: =MIN(_xlfn.MINIFS(W$59:W$73,$D$59:$D$73,$D41),(W$53*W26/SUM(W$25:W$29))) -> 5785.9445 | X41: =MIN(_xlfn.MINIFS(X$59:X$73,$D$59:$D$73,$D41),(X$53*X26/SUM(X$25:X$29))) -> 5785.9445 | Y41: =MIN(_xlfn.MINIFS(Y$59:Y$73,$D$59:$D$73,$D41),(Y$53*Y26/SUM(Y$25:Y$29))) -> 5785.9445 | Z41: =MIN(_xlfn.MINIFS(Z$59:Z$73,$D$59:$D$73,$D41),(Z$53*Z26/SUM(Z$25:Z$29))) -> 5785.9445 | ... BM41: =MIN(_xlfn.MINIFS(BM$59:BM$73,$D$59:$D$73,$D41),(BM$53*BM26/SUM(BM$25:BM$29))) -> 76493.974
D42: Hoplens (FTA) 980 | F42: =_xlfn.MINIFS(F$54:F$73,$D$54:$D$73,$D42) -> 7646.3705 | G42: =_xlfn.MINIFS(G$54:G$73,$D$54:$D$73,$D42) -> 7646.3705 | H42: =_xlfn.MINIFS(H$54:H$73,$D$54:$D$73,$D42) -> 9175.6446 | I42: =_xlfn.MINIFS(I$54:I$73,$D$54:$D$73,$D42) -> 10704.919 | J42: =_xlfn.MINIFS(J$54:J$73,$D$54:$D$73,$D42) -> 10704.919 | K42: =_xlfn.MINIFS(K$54:K$73,$D$54:$D$73,$D42) -> 10704.919 | L42: =_xlfn.MINIFS(L$54:L$73,$D$54:$D$73,$D42) -> 10704.919 | M42: =_xlfn.MINIFS(M$54:M$73,$D$54:$D$73,$D42) -> 10704.919 | ... R42: =_xlfn.MINIFS(R$54:R$73,$D$54:$D$73,$D42) -> 10704.919 | S42: =MIN(_xlfn.MINIFS(S$59:S$73,$D$59:$D$73,$D42),(S$53*S27/SUM(S$25:S$29))) -> 131517.57 | T42: =MIN(_xlfn.MINIFS(T$59:T$73,$D$59:$D$73,$D42),(T$53*T27/SUM(T$25:T$29))) -> 9456.703 | U42: =MIN(_xlfn.MINIFS(U$59:U$73,$D$59:$D$73,$D42),(U$53*U27/SUM(U$25:U$29))) -> 9456.703 | V42: =MIN(_xlfn.MINIFS(V$59:V$73,$D$59:$D$73,$D42),(V$53*V27/SUM(V$25:V$29))) -> 9456.703 | W42: =MIN(_xlfn.MINIFS(W$59:W$73,$D$59:$D$73,$D42),(W$53*W27/SUM(W$25:W$29))) -> 9456.703 | X42: =MIN(_xlfn.MINIFS(X$59:X$73,$D$59:$D$73,$D42),(X$53*X27/SUM(X$25:X$29))) -> 9456.703 | Y42: =MIN(_xlfn.MINIFS(Y$59:Y$73,$D$59:$D$73,$D42),(Y$53*Y27/SUM(Y$25:Y$29))) -> 9456.703 | Z42: =MIN(_xlfn.MINIFS(Z$59:Z$73,$D$59:$D$73,$D42),(Z$53*Z27/SUM(Z$25:Z$29))) -> 9456.703 | ... BM42: =MIN(_xlfn.MINIFS(BM$59:BM$73,$D$59:$D$73,$D42),(BM$53*BM27/SUM(BM$25:BM$29))) -> 266720.95
...
